2016-05-12 21:38:34,122 [Thread-2:10056] [django.request:284] [base:handle_uncaught_exception] [ERROR]- Internal Server Error: /
Traceback (most recent call last):
  File "D:\Python27\lib\site-packages\django\core\handlers\base.py", line 149, in get_response
    response = self.process_exception_by_middleware(e, request)
  File "D:\Python27\lib\site-packages\django\core\handlers\base.py", line 147, in get_response
    response = wrapped_callback(request, *callback_args, **callback_kwargs)
  File "D:\workspace\OnlineLibrary\src\OnlineLibraryApp\views.py", line 43, in index
    return render(request, 'index.html', locals())
  File "D:\Python27\lib\site-packages\django\shortcuts.py", line 67, in render
    template_name, context, request=request, using=using)
  File "D:\Python27\lib\site-packages\django\template\loader.py", line 97, in render_to_string
    return template.render(context, request)
  File "D:\Python27\lib\site-packages\django\template\backends\django.py", line 95, in render
    return self.template.render(context)
  File "D:\Python27\lib\site-packages\django\template\base.py", line 204, in render
    with context.bind_template(self):
  File "D:\Python27\lib\contextlib.py", line 17, in __enter__
    return self.gen.next()
  File "D:\Python27\lib\site-packages\django\template\context.py", line 256, in bind_template
    processors = (template.engine.template_context_processors +
  File "D:\Python27\lib\site-packages\django\utils\functional.py", line 33, in __get__
    res = instance.__dict__[self.name] = self.func(instance)
  File "D:\Python27\lib\site-packages\django\template\engine.py", line 105, in template_context_processors
    return tuple(import_string(path) for path in context_processors)
  File "D:\Python27\lib\site-packages\django\template\engine.py", line 105, in <genexpr>
    return tuple(import_string(path) for path in context_processors)
  File "D:\Python27\lib\site-packages\django\utils\module_loading.py", line 20, in import_string
    module = import_module(module_path)
  File "D:\Python27\lib\importlib\__init__.py", line 37, in import_module
    __import__(name)
ImportError: No module named blog.views
2016-05-12 21:39:14,628 [Thread-2:2332] [django.request:284] [base:handle_uncaught_exception] [ERROR]- Internal Server Error: /
Traceback (most recent call last):
  File "D:\Python27\lib\site-packages\django\core\handlers\base.py", line 149, in get_response
    response = self.process_exception_by_middleware(e, request)
  File "D:\Python27\lib\site-packages\django\core\handlers\base.py", line 147, in get_response
    response = wrapped_callback(request, *callback_args, **callback_kwargs)
  File "D:\workspace\OnlineLibrary\src\OnlineLibraryApp\views.py", line 43, in index
    return render(request, 'index.html', locals())
  File "D:\Python27\lib\site-packages\django\shortcuts.py", line 67, in render
    template_name, context, request=request, using=using)
  File "D:\Python27\lib\site-packages\django\template\loader.py", line 97, in render_to_string
    return template.render(context, request)
  File "D:\Python27\lib\site-packages\django\template\backends\django.py", line 95, in render
    return self.template.render(context)
  File "D:\Python27\lib\site-packages\django\template\base.py", line 204, in render
    with context.bind_template(self):
  File "D:\Python27\lib\contextlib.py", line 17, in __enter__
    return self.gen.next()
  File "D:\Python27\lib\site-packages\django\template\context.py", line 256, in bind_template
    processors = (template.engine.template_context_processors +
  File "D:\Python27\lib\site-packages\django\utils\functional.py", line 33, in __get__
    res = instance.__dict__[self.name] = self.func(instance)
  File "D:\Python27\lib\site-packages\django\template\engine.py", line 105, in template_context_processors
    return tuple(import_string(path) for path in context_processors)
  File "D:\Python27\lib\site-packages\django\template\engine.py", line 105, in <genexpr>
    return tuple(import_string(path) for path in context_processors)
  File "D:\Python27\lib\site-packages\django\utils\module_loading.py", line 27, in import_string
    six.reraise(ImportError, ImportError(msg), sys.exc_info()[2])
  File "D:\Python27\lib\site-packages\django\utils\module_loading.py", line 23, in import_string
    return getattr(module, class_name)
ImportError: Module "OnlineLibraryApp.views" does not define a "global_settings" attribute/class
2016-05-12 21:39:45,854 [Thread-2:9872] [django.request:284] [base:handle_uncaught_exception] [ERROR]- Internal Server Error: /
Traceback (most recent call last):
  File "D:\Python27\lib\site-packages\django\core\handlers\base.py", line 149, in get_response
    response = self.process_exception_by_middleware(e, request)
  File "D:\Python27\lib\site-packages\django\core\handlers\base.py", line 147, in get_response
    response = wrapped_callback(request, *callback_args, **callback_kwargs)
  File "D:\workspace\OnlineLibrary\src\OnlineLibraryApp\views.py", line 43, in index
    return render(request, 'index.html', locals())
  File "D:\Python27\lib\site-packages\django\shortcuts.py", line 67, in render
    template_name, context, request=request, using=using)
  File "D:\Python27\lib\site-packages\django\template\loader.py", line 97, in render_to_string
    return template.render(context, request)
  File "D:\Python27\lib\site-packages\django\template\backends\django.py", line 95, in render
    return self.template.render(context)
  File "D:\Python27\lib\site-packages\django\template\base.py", line 204, in render
    with context.bind_template(self):
  File "D:\Python27\lib\contextlib.py", line 17, in __enter__
    return self.gen.next()
  File "D:\Python27\lib\site-packages\django\template\context.py", line 260, in bind_template
    updates.update(processor(self.request))
ValueError: dictionary update sequence element #0 has length 8; 2 is required
2016-05-12 21:49:33,809 [Thread-35:11176] [django.request:284] [base:handle_uncaught_exception] [ERROR]- Internal Server Error: /admin/OnlineLibraryApp/comment/
Traceback (most recent call last):
  File "D:\Python27\lib\site-packages\django\core\handlers\base.py", line 149, in get_response
    response = self.process_exception_by_middleware(e, request)
  File "D:\Python27\lib\site-packages\django\core\handlers\base.py", line 147, in get_response
    response = wrapped_callback(request, *callback_args, **callback_kwargs)
  File "D:\Python27\lib\site-packages\django\contrib\admin\options.py", line 541, in wrapper
    return self.admin_site.admin_view(view)(*args, **kwargs)
  File "D:\Python27\lib\site-packages\django\utils\decorators.py", line 149, in _wrapped_view
    response = view_func(request, *args, **kwargs)
  File "D:\Python27\lib\site-packages\django\views\decorators\cache.py", line 57, in _wrapped_view_func
    response = view_func(request, *args, **kwargs)
  File "D:\Python27\lib\site-packages\django\contrib\admin\sites.py", line 244, in inner
    return view(request, *args, **kwargs)
  File "D:\Python27\lib\site-packages\django\utils\decorators.py", line 67, in _wrapper
    return bound_func(*args, **kwargs)
  File "D:\Python27\lib\site-packages\django\utils\decorators.py", line 149, in _wrapped_view
    response = view_func(request, *args, **kwargs)
  File "D:\Python27\lib\site-packages\django\utils\decorators.py", line 63, in bound_func
    return func.__get__(self, type(self))(*args2, **kwargs2)
  File "D:\Python27\lib\site-packages\django\contrib\admin\options.py", line 1496, in changelist_view
    response = self.response_action(request, queryset=cl.get_queryset(request))
  File "D:\Python27\lib\site-packages\django\contrib\admin\options.py", line 1245, in response_action
    response = func(self, request, queryset)
  File "D:\Python27\lib\site-packages\django\contrib\admin\actions.py", line 37, in delete_selected
    queryset, opts, request.user, modeladmin.admin_site, using)
  File "D:\Python27\lib\site-packages\django\contrib\admin\utils.py", line 163, in get_deleted_objects
    to_delete = collector.nested(format_callback)
  File "D:\Python27\lib\site-packages\django\contrib\admin\utils.py", line 223, in nested
    roots.extend(self._nested(root, seen, format_callback))
  File "D:\Python27\lib\site-packages\django\contrib\admin\utils.py", line 209, in _nested
    ret = [format_callback(obj)]
  File "D:\Python27\lib\site-packages\django\contrib\admin\utils.py", line 136, in format_callback
    force_text(obj))
  File "D:\Python27\lib\site-packages\django\utils\encoding.py", line 78, in force_text
    s = six.text_type(s)
  File "D:\workspace\OnlineLibrary\src\OnlineLibraryApp\models.py", line 81, in __unicode__
    return self.book.name
  File "D:\Python27\lib\site-packages\django\db\models\fields\related_descriptors.py", line 169, in __get__
    rel_obj = qs.get()
  File "D:\Python27\lib\site-packages\django\db\models\query.py", line 387, in get
    self.model._meta.object_name
DoesNotExist: Book matching query does not exist.
2016-05-12 23:54:21,878 [Thread-14:6104] [django.request:182] [base:get_response] [WARNING]- Not Found: /booklist.html
2016-05-12 23:54:56,946 [Thread-15:10824] [django.request:182] [base:get_response] [WARNING]- Not Found: /booklist.html
2016-05-12 23:59:08,851 [Thread-2:10972] [django.request:182] [base:get_response] [WARNING]- Not Found: /booklist.html
2016-05-13 00:17:03,809 [Thread-2:10552] [django.request:284] [base:handle_uncaught_exception] [ERROR]- Internal Server Error: /booklist/
Traceback (most recent call last):
  File "D:\Python27\lib\site-packages\django\core\handlers\base.py", line 149, in get_response
    response = self.process_exception_by_middleware(e, request)
  File "D:\Python27\lib\site-packages\django\core\handlers\base.py", line 147, in get_response
    response = wrapped_callback(request, *callback_args, **callback_kwargs)
  File "D:\workspace\OnlineLibrary\src\OnlineLibraryApp\views.py", line 70, in booklist
    return render(request, 'booklist.html', locals())
  File "D:\Python27\lib\site-packages\django\shortcuts.py", line 67, in render
    template_name, context, request=request, using=using)
  File "D:\Python27\lib\site-packages\django\template\loader.py", line 97, in render_to_string
    return template.render(context, request)
  File "D:\Python27\lib\site-packages\django\template\backends\django.py", line 95, in render
    return self.template.render(context)
  File "D:\Python27\lib\site-packages\django\template\base.py", line 206, in render
    return self._render(context)
  File "D:\Python27\lib\site-packages\django\template\base.py", line 197, in _render
    return self.nodelist.render(context)
  File "D:\Python27\lib\site-packages\django\template\base.py", line 992, in render
    bit = node.render_annotated(context)
  File "D:\Python27\lib\site-packages\django\template\base.py", line 959, in render_annotated
    return self.render(context)
  File "D:\Python27\lib\site-packages\django\template\loader_tags.py", line 173, in render
    return compiled_parent._render(context)
  File "D:\Python27\lib\site-packages\django\template\base.py", line 197, in _render
    return self.nodelist.render(context)
  File "D:\Python27\lib\site-packages\django\template\base.py", line 992, in render
    bit = node.render_annotated(context)
  File "D:\Python27\lib\site-packages\django\template\base.py", line 959, in render_annotated
    return self.render(context)
  File "D:\Python27\lib\site-packages\django\template\loader_tags.py", line 69, in render
    result = block.nodelist.render(context)
  File "D:\Python27\lib\site-packages\django\template\base.py", line 992, in render
    bit = node.render_annotated(context)
  File "D:\Python27\lib\site-packages\django\template\base.py", line 959, in render_annotated
    return self.render(context)
  File "D:\Python27\lib\site-packages\django\template\defaulttags.py", line 167, in render
    values = list(values)
TypeError: 'Manager' object is not iterable
2016-05-13 00:19:46,829 [Thread-60:10312] [django.request:284] [base:handle_uncaught_exception] [ERROR]- Internal Server Error: /booklist/
Traceback (most recent call last):
  File "D:\Python27\lib\site-packages\django\core\handlers\base.py", line 149, in get_response
    response = self.process_exception_by_middleware(e, request)
  File "D:\Python27\lib\site-packages\django\core\handlers\base.py", line 147, in get_response
    response = wrapped_callback(request, *callback_args, **callback_kwargs)
  File "D:\workspace\OnlineLibrary\src\OnlineLibraryApp\views.py", line 70, in booklist
    return render(request, 'booklist.html', locals())
  File "D:\Python27\lib\site-packages\django\shortcuts.py", line 67, in render
    template_name, context, request=request, using=using)
  File "D:\Python27\lib\site-packages\django\template\loader.py", line 97, in render_to_string
    return template.render(context, request)
  File "D:\Python27\lib\site-packages\django\template\backends\django.py", line 95, in render
    return self.template.render(context)
  File "D:\Python27\lib\site-packages\django\template\base.py", line 206, in render
    return self._render(context)
  File "D:\Python27\lib\site-packages\django\template\base.py", line 197, in _render
    return self.nodelist.render(context)
  File "D:\Python27\lib\site-packages\django\template\base.py", line 992, in render
    bit = node.render_annotated(context)
  File "D:\Python27\lib\site-packages\django\template\base.py", line 959, in render_annotated
    return self.render(context)
  File "D:\Python27\lib\site-packages\django\template\loader_tags.py", line 173, in render
    return compiled_parent._render(context)
  File "D:\Python27\lib\site-packages\django\template\base.py", line 197, in _render
    return self.nodelist.render(context)
  File "D:\Python27\lib\site-packages\django\template\base.py", line 992, in render
    bit = node.render_annotated(context)
  File "D:\Python27\lib\site-packages\django\template\base.py", line 959, in render_annotated
    return self.render(context)
  File "D:\Python27\lib\site-packages\django\template\loader_tags.py", line 69, in render
    result = block.nodelist.render(context)
  File "D:\Python27\lib\site-packages\django\template\base.py", line 992, in render
    bit = node.render_annotated(context)
  File "D:\Python27\lib\site-packages\django\template\base.py", line 959, in render_annotated
    return self.render(context)
  File "D:\Python27\lib\site-packages\django\template\defaulttags.py", line 167, in render
    values = list(values)
TypeError: 'Manager' object is not iterable
2016-05-13 00:19:59,869 [Thread-62:11160] [django.request:284] [base:handle_uncaught_exception] [ERROR]- Internal Server Error: /booklist/
Traceback (most recent call last):
  File "D:\Python27\lib\site-packages\django\core\handlers\base.py", line 149, in get_response
    response = self.process_exception_by_middleware(e, request)
  File "D:\Python27\lib\site-packages\django\core\handlers\base.py", line 147, in get_response
    response = wrapped_callback(request, *callback_args, **callback_kwargs)
  File "D:\workspace\OnlineLibrary\src\OnlineLibraryApp\views.py", line 70, in booklist
    return render(request, 'booklist.html', locals())
  File "D:\Python27\lib\site-packages\django\shortcuts.py", line 67, in render
    template_name, context, request=request, using=using)
  File "D:\Python27\lib\site-packages\django\template\loader.py", line 97, in render_to_string
    return template.render(context, request)
  File "D:\Python27\lib\site-packages\django\template\backends\django.py", line 95, in render
    return self.template.render(context)
  File "D:\Python27\lib\site-packages\django\template\base.py", line 206, in render
    return self._render(context)
  File "D:\Python27\lib\site-packages\django\template\base.py", line 197, in _render
    return self.nodelist.render(context)
  File "D:\Python27\lib\site-packages\django\template\base.py", line 992, in render
    bit = node.render_annotated(context)
  File "D:\Python27\lib\site-packages\django\template\base.py", line 959, in render_annotated
    return self.render(context)
  File "D:\Python27\lib\site-packages\django\template\loader_tags.py", line 173, in render
    return compiled_parent._render(context)
  File "D:\Python27\lib\site-packages\django\template\base.py", line 197, in _render
    return self.nodelist.render(context)
  File "D:\Python27\lib\site-packages\django\template\base.py", line 992, in render
    bit = node.render_annotated(context)
  File "D:\Python27\lib\site-packages\django\template\base.py", line 959, in render_annotated
    return self.render(context)
  File "D:\Python27\lib\site-packages\django\template\loader_tags.py", line 69, in render
    result = block.nodelist.render(context)
  File "D:\Python27\lib\site-packages\django\template\base.py", line 992, in render
    bit = node.render_annotated(context)
  File "D:\Python27\lib\site-packages\django\template\base.py", line 959, in render_annotated
    return self.render(context)
  File "D:\Python27\lib\site-packages\django\template\defaulttags.py", line 167, in render
    values = list(values)
TypeError: 'Manager' object is not iterable
2016-05-13 00:21:59,174 [Thread-2:10600] [django.request:284] [base:handle_uncaught_exception] [ERROR]- Internal Server Error: /
Traceback (most recent call last):
  File "D:\Python27\lib\site-packages\django\core\handlers\base.py", line 149, in get_response
    response = self.process_exception_by_middleware(e, request)
  File "D:\Python27\lib\site-packages\django\core\handlers\base.py", line 147, in get_response
    response = wrapped_callback(request, *callback_args, **callback_kwargs)
  File "D:\workspace\OnlineLibrary\src\OnlineLibraryApp\views.py", line 46, in index
    index_bookList = Book.objects[:12]
TypeError: 'Manager' object has no attribute '__getitem__'
2016-05-13 00:26:01,101 [Thread-2:11228] [django.request:284] [base:handle_uncaught_exception] [ERROR]- Internal Server Error: /
Traceback (most recent call last):
  File "D:\Python27\lib\site-packages\django\core\handlers\base.py", line 149, in get_response
    response = self.process_exception_by_middleware(e, request)
  File "D:\Python27\lib\site-packages\django\core\handlers\base.py", line 147, in get_response
    response = wrapped_callback(request, *callback_args, **callback_kwargs)
  File "D:\workspace\OnlineLibrary\src\OnlineLibraryApp\views.py", line 44, in index
    index_bookList = Book.objects[:12]
TypeError: 'Manager' object has no attribute '__getitem__'
2016-05-13 00:26:02,414 [Thread-3:6104] [django.request:284] [base:handle_uncaught_exception] [ERROR]- Internal Server Error: /
Traceback (most recent call last):
  File "D:\Python27\lib\site-packages\django\core\handlers\base.py", line 149, in get_response
    response = self.process_exception_by_middleware(e, request)
  File "D:\Python27\lib\site-packages\django\core\handlers\base.py", line 147, in get_response
    response = wrapped_callback(request, *callback_args, **callback_kwargs)
  File "D:\workspace\OnlineLibrary\src\OnlineLibraryApp\views.py", line 44, in index
    index_bookList = Book.objects[:12]
TypeError: 'Manager' object has no attribute '__getitem__'
2016-05-13 01:30:19,013 [Thread-15:10540] [django.request:182] [base:get_response] [WARNING]- Not Found: /booklist/category
2016-05-13 01:35:58,035 [Thread-61:12188] [django.request:182] [base:get_response] [WARNING]- Not Found: /booklist/category
2016-05-13 01:36:04,177 [Thread-72:11936] [django.request:182] [base:get_response] [WARNING]- Not Found: /booklist/index/category
2016-05-13 01:36:06,233 [Thread-73:11964] [django.request:182] [base:get_response] [WARNING]- Not Found: /booklist/index/category
2016-05-13 02:16:52,266 [Thread-69:12084] [django.request:182] [base:get_response] [WARNING]- Not Found: /category/index/category
2016-05-13 02:16:56,882 [Thread-70:9832] [django.request:182] [base:get_response] [WARNING]- Not Found: /category/index/category
2016-05-13 02:17:00,654 [Thread-81:11564] [django.request:182] [base:get_response] [WARNING]- Not Found: /category/.category
2016-05-13 02:19:45,634 [Thread-133:11488] [django.request:182] [base:get_response] [WARNING]- Not Found: /booklist/category
2016-05-13 02:20:10,776 [Thread-155:9348] [django.request:182] [base:get_response] [WARNING]- Not Found: /booklist/category
